[2024-02-16T22:10:34.296+0000] {taskinstance.py:1956} INFO - Dependencies all met for dep_context=non-requeueable deps ti=<TaskInstance: hadoop_elt_pipeline.step_3_run_hadoop_job manual__2024-02-16T22:10:20.613646+00:00 [queued]>
[2024-02-16T22:10:34.315+0000] {taskinstance.py:1956} INFO - Dependencies all met for dep_context=requeueable deps ti=<TaskInstance: hadoop_elt_pipeline.step_3_run_hadoop_job manual__2024-02-16T22:10:20.613646+00:00 [queued]>
[2024-02-16T22:10:34.316+0000] {taskinstance.py:2170} INFO - Starting attempt 1 of 2
[2024-02-16T22:10:34.369+0000] {taskinstance.py:2191} INFO - Executing <Task(PythonOperator): step_3_run_hadoop_job> on 2024-02-16 22:10:20.613646+00:00
[2024-02-16T22:10:34.375+0000] {standard_task_runner.py:60} INFO - Started process 206 to run task
[2024-02-16T22:10:34.379+0000] {standard_task_runner.py:87} INFO - Running: ['airflow', 'tasks', 'run', 'hadoop_elt_pipeline', 'step_3_run_hadoop_job', 'manual__2024-02-16T22:10:20.613646+00:00', '--job-id', '5', '--raw', '--subdir', 'DAGS_FOLDER/ELT_automated_airflow.py', '--cfg-path', '/tmp/tmpmovczqos']
[2024-02-16T22:10:34.383+0000] {standard_task_runner.py:88} INFO - Job 5: Subtask step_3_run_hadoop_job
[2024-02-16T22:10:34.501+0000] {task_command.py:423} INFO - Running <TaskInstance: hadoop_elt_pipeline.step_3_run_hadoop_job manual__2024-02-16T22:10:20.613646+00:00 [running]> on host a1bb76e936e6
[2024-02-16T22:10:34.720+0000] {taskinstance.py:2480} INFO - Exporting env vars: AIRFLOW_CTX_DAG_OWNER='airflow' AIRFLOW_CTX_DAG_ID='hadoop_elt_pipeline' AIRFLOW_CTX_TASK_ID='step_3_run_hadoop_job' AIRFLOW_CTX_EXECUTION_DATE='2024-02-16T22:10:20.613646+00:00' AIRFLOW_CTX_TRY_NUMBER='1' AIRFLOW_CTX_DAG_RUN_ID='manual__2024-02-16T22:10:20.613646+00:00'
[2024-02-16T22:10:34.733+0000] {logging_mixin.py:188} INFO - Error occurred: Command 'hadoop jar C:\Users\LENOVO\hadoop-3.3.0\hadoop-3.3.0\share\hadoop\tools\lib\hadoop-streaming-3.3.0.jar -files file:/C:/Users/LENOVO/ETL-and-ELT-integration-pipelines/mapper.py -mapper "python mapper.py" -input /sales_data/* -output /output-sales-data' returned non-zero exit status 127.
[2024-02-16T22:10:34.734+0000] {python.py:201} INFO - Done. Returned value was: None
[2024-02-16T22:10:34.751+0000] {taskinstance.py:1138} INFO - Marking task as SUCCESS. dag_id=hadoop_elt_pipeline, task_id=step_3_run_hadoop_job, execution_date=20240216T221020, start_date=20240216T221034, end_date=20240216T221034
[2024-02-16T22:10:34.802+0000] {local_task_job_runner.py:234} INFO - Task exited with return code 0
[2024-02-16T22:10:34.839+0000] {taskinstance.py:3280} INFO - 0 downstream tasks scheduled from follow-on schedule check
