[2024-02-18T18:18:07.928+0000] {taskinstance.py:1956} INFO - Dependencies all met for dep_context=non-requeueable deps ti=<TaskInstance: ETL_pipeline.run_etl_process scheduled__2023-07-20T00:00:00+00:00 [queued]>
[2024-02-18T18:18:07.950+0000] {taskinstance.py:1956} INFO - Dependencies all met for dep_context=requeueable deps ti=<TaskInstance: ETL_pipeline.run_etl_process scheduled__2023-07-20T00:00:00+00:00 [queued]>
[2024-02-18T18:18:07.950+0000] {taskinstance.py:2170} INFO - Starting attempt 1 of 2
[2024-02-18T18:18:08.010+0000] {taskinstance.py:2191} INFO - Executing <Task(PythonOperator): run_etl_process> on 2023-07-20 00:00:00+00:00
[2024-02-18T18:18:08.016+0000] {standard_task_runner.py:60} INFO - Started process 6845 to run task
[2024-02-18T18:18:08.020+0000] {standard_task_runner.py:87} INFO - Running: ['airflow', 'tasks', 'run', 'ETL_pipeline', 'run_etl_process', 'scheduled__2023-07-20T00:00:00+00:00', '--job-id', '319', '--raw', '--subdir', 'DAGS_FOLDER/ETL_automated_airflow.py', '--cfg-path', '/tmp/tmpp2sla6sf']
[2024-02-18T18:18:08.022+0000] {standard_task_runner.py:88} INFO - Job 319: Subtask run_etl_process
[2024-02-18T18:18:08.148+0000] {task_command.py:423} INFO - Running <TaskInstance: ETL_pipeline.run_etl_process scheduled__2023-07-20T00:00:00+00:00 [running]> on host 8bb8949050c9
[2024-02-18T18:18:08.356+0000] {taskinstance.py:2480} INFO - Exporting env vars: AIRFLOW_CTX_DAG_OWNER='airflow' AIRFLOW_CTX_DAG_ID='ETL_pipeline' AIRFLOW_CTX_TASK_ID='run_etl_process' AIRFLOW_CTX_EXECUTION_DATE='2023-07-20T00:00:00+00:00' AIRFLOW_CTX_TRY_NUMBER='1' AIRFLOW_CTX_DAG_RUN_ID='scheduled__2023-07-20T00:00:00+00:00'
[2024-02-18T18:18:08.359+0000] {taskinstance.py:2698} ERROR - Task failed with exception
Traceback (most recent call last):
  File "/home/airflow/.local/lib/python3.8/site-packages/airflow/models/taskinstance.py", line 433, in _execute_task
    result = execute_callable(context=context, **execute_callable_kwargs)
  File "/home/airflow/.local/lib/python3.8/site-packages/airflow/operators/python.py", line 199, in execute
    return_value = self.execute_callable()
  File "/home/airflow/.local/lib/python3.8/site-packages/airflow/operators/python.py", line 216, in execute_callable
    return self.python_callable(*self.op_args, **self.op_kwargs)
  File "/opt/airflow/dags/ETL_automated_airflow.py", line 175, in etl_task
    process_files(csv_directory, table_name)
  File "/opt/airflow/dags/ETL_automated_airflow.py", line 115, in process_files
    conn = create_db_connection()
  File "/opt/airflow/dags/ETL_automated_airflow.py", line 32, in create_db_connection
    conn = psycopg2.connect(dbname=db_name, user=username, password=password)
NameError: name 'db_name' is not defined
[2024-02-18T18:18:08.382+0000] {taskinstance.py:1138} INFO - Marking task as UP_FOR_RETRY. dag_id=ETL_pipeline, task_id=run_etl_process, execution_date=20230720T000000, start_date=20240218T181807, end_date=20240218T181808
[2024-02-18T18:18:08.437+0000] {standard_task_runner.py:107} ERROR - Failed to execute job 319 for task run_etl_process (name 'db_name' is not defined; 6845)
[2024-02-18T18:18:08.475+0000] {local_task_job_runner.py:234} INFO - Task exited with return code 1
[2024-02-18T18:18:08.510+0000] {taskinstance.py:3280} INFO - 0 downstream tasks scheduled from follow-on schedule check
